<?xml version="1.0" encoding="UTF-8"?>
<testng-results skipped="0" failed="1" total="1" passed="0">
  <reporter-output>
  </reporter-output>
  <suite name="Default suite" duration-ms="33602" started-at="2018-02-13T09:46:48Z" finished-at="2018-02-13T09:47:21Z">
    <groups>
    </groups>
    <test name="Default test" duration-ms="33602" started-at="2018-02-13T09:46:48Z" finished-at="2018-02-13T09:47:21Z">
      <class name="testCases.DeletingUser">
        <test-method status="PASS" signature="setUp()[pri:0, instance:testCases.DeletingUser@3daa422a]" name="setUp" is-config="true" duration-ms="1314" started-at="2018-02-13T15:16:46Z" finished-at="2018-02-13T15:16:48Z">
          <reporter-output>
          </reporter-output>
        </test-method> <!-- setUp -->
        <test-method status="PASS" signature="AppOrangeHRMLogin()[pri:0, instance:testCases.DeletingUser@3daa422a]" name="AppOrangeHRMLogin" is-config="true" duration-ms="28463" started-at="2018-02-13T15:16:48Z" finished-at="2018-02-13T15:17:16Z">
          <reporter-output>
          </reporter-output>
        </test-method> <!-- AppOrangeHRMLogin -->
        <test-method status="FAIL" signature="deleteUser()[pri:0, instance:testCases.DeletingUser@3daa422a]" name="deleteUser" duration-ms="5029" started-at="2018-02-13T15:17:16Z" finished-at="2018-02-13T15:17:21Z">
          <exception class="java.lang.AssertionError">
            <message>
              <![CDATA[The following asserts failed:
null]]>
            </message>
            <full-stacktrace>
              <![CDATA[java.lang.AssertionError: The following asserts failed:
null
	at org.testng.asserts.SoftAssert.assertAll(SoftAssert.java:37)
	at testCases.DeletingUser.deleteUser(DeletingUser.java:72)
	at sun.reflect.NativeMethodAccessorImpl.invoke0(Native Method)
	at sun.reflect.NativeMethodAccessorImpl.invoke(Unknown Source)
	at sun.reflect.DelegatingMethodAccessorImpl.invoke(Unknown Source)
	at java.lang.reflect.Method.invoke(Unknown Source)
	at org.testng.internal.MethodInvocationHelper.invokeMethod(MethodInvocationHelper.java:80)
	at org.testng.internal.Invoker.invokeMethod(Invoker.java:714)
	at org.testng.internal.Invoker.invokeTestMethod(Invoker.java:901)
	at org.testng.internal.Invoker.invokeTestMethods(Invoker.java:1231)
	at org.testng.internal.TestMethodWorker.invokeTestMethods(TestMethodWorker.java:127)
	at org.testng.internal.TestMethodWorker.run(TestMethodWorker.java:111)
	at org.testng.TestRunner.privateRun(TestRunner.java:767)
	at org.testng.TestRunner.run(TestRunner.java:617)
	at org.testng.SuiteRunner.runTest(SuiteRunner.java:334)
	at org.testng.SuiteRunner.runSequentially(SuiteRunner.java:329)
	at org.testng.SuiteRunner.privateRun(SuiteRunner.java:291)
	at org.testng.SuiteRunner.run(SuiteRunner.java:240)
	at org.testng.SuiteRunnerWorker.runSuite(SuiteRunnerWorker.java:52)
	at org.testng.SuiteRunnerWorker.run(SuiteRunnerWorker.java:86)
	at org.testng.TestNG.runSuitesSequentially(TestNG.java:1198)
	at org.testng.TestNG.runSuitesLocally(TestNG.java:1123)
	at org.testng.TestNG.run(TestNG.java:1031)
	at org.testng.remote.AbstractRemoteTestNG.run(AbstractRemoteTestNG.java:114)
	at org.testng.remote.RemoteTestNG.initAndRun(RemoteTestNG.java:251)
	at org.testng.remote.RemoteTestNG.main(RemoteTestNG.java:77)
]]>
            </full-stacktrace>
          </exception> <!-- java.lang.AssertionError -->
          <reporter-output>
          </reporter-output>
        </test-method> <!-- deleteUser -->
        <test-method status="FAIL" signature="getResult(org.testng.ITestResult)[pri:0, instance:testCases.DeletingUser@3daa422a]" name="getResult" is-config="true" duration-ms="0" started-at="2018-02-13T15:17:21Z" finished-at="2018-02-13T15:17:21Z">
          <params>
            <param index="0">
              <value>
                <![CDATA[[TestResult name=deleteUser status=FAILURE method=DeletingUser.deleteUser()[pri:0, instance:testCases.DeletingUser@3daa422a] output={null}]]]>
              </value>
            </param>
          </params>
          <exception class="java.lang.NullPointerException">
            <full-stacktrace>
              <![CDATA[java.lang.NullPointerException
	at utility.GetScreenshot.capture(GetScreenshot.java:16)
	at utility.BaseExtentTest.getResult(BaseExtentTest.java:44)
	at sun.reflect.NativeMethodAccessorImpl.invoke0(Native Method)
	at sun.reflect.NativeMethodAccessorImpl.invoke(Unknown Source)
	at sun.reflect.DelegatingMethodAccessorImpl.invoke(Unknown Source)
	at java.lang.reflect.Method.invoke(Unknown Source)
	at org.testng.internal.MethodInvocationHelper.invokeMethod(MethodInvocationHelper.java:80)
	at org.testng.internal.Invoker.invokeConfigurationMethod(Invoker.java:564)
	at org.testng.internal.Invoker.invokeConfigurations(Invoker.java:213)
	at org.testng.internal.Invoker.invokeMethod(Invoker.java:786)
	at org.testng.internal.Invoker.invokeTestMethod(Invoker.java:901)
	at org.testng.internal.Invoker.invokeTestMethods(Invoker.java:1231)
	at org.testng.internal.TestMethodWorker.invokeTestMethods(TestMethodWorker.java:127)
	at org.testng.internal.TestMethodWorker.run(TestMethodWorker.java:111)
	at org.testng.TestRunner.privateRun(TestRunner.java:767)
	at org.testng.TestRunner.run(TestRunner.java:617)
	at org.testng.SuiteRunner.runTest(SuiteRunner.java:334)
	at org.testng.SuiteRunner.runSequentially(SuiteRunner.java:329)
	at org.testng.SuiteRunner.privateRun(SuiteRunner.java:291)
	at org.testng.SuiteRunner.run(SuiteRunner.java:240)
	at org.testng.SuiteRunnerWorker.runSuite(SuiteRunnerWorker.java:52)
	at org.testng.SuiteRunnerWorker.run(SuiteRunnerWorker.java:86)
	at org.testng.TestNG.runSuitesSequentially(TestNG.java:1198)
	at org.testng.TestNG.runSuitesLocally(TestNG.java:1123)
	at org.testng.TestNG.run(TestNG.java:1031)
	at org.testng.remote.AbstractRemoteTestNG.run(AbstractRemoteTestNG.java:114)
	at org.testng.remote.RemoteTestNG.initAndRun(RemoteTestNG.java:251)
	at org.testng.remote.RemoteTestNG.main(RemoteTestNG.java:77)
]]>
            </full-stacktrace>
          </exception> <!-- java.lang.NullPointerException -->
          <reporter-output>
          </reporter-output>
        </test-method> <!-- getResult -->
        <test-method status="SKIP" signature="Logout()[pri:0, instance:testCases.DeletingUser@3daa422a]" name="Logout" is-config="true" duration-ms="0" started-at="2018-02-13T15:17:21Z" finished-at="2018-02-13T15:17:21Z">
          <reporter-output>
          </reporter-output>
        </test-method> <!-- Logout -->
        <test-method status="SKIP" signature="teardown()[pri:0, instance:testCases.DeletingUser@3daa422a]" name="teardown" is-config="true" duration-ms="0" started-at="2018-02-13T15:17:22Z" finished-at="2018-02-13T15:17:22Z">
          <reporter-output>
          </reporter-output>
        </test-method> <!-- teardown -->
      </class> <!-- testCases.DeletingUser -->
    </test> <!-- Default test -->
  </suite> <!-- Default suite -->
</testng-results>
